[2025-01-08T03:22:19.584+0000] {local_task_job_runner.py:123} INFO - ::group::Pre task execution logs
[2025-01-08T03:22:19.606+0000] {taskinstance.py:2613} INFO - Dependencies all met for dep_context=non-requeueable deps ti=<TaskInstance: dag_with_postgres_operator_v02.insert_into_key_table manual__2025-01-08T02:56:58.038560+00:00 [queued]>
[2025-01-08T03:22:19.618+0000] {taskinstance.py:2613} INFO - Dependencies all met for dep_context=requeueable deps ti=<TaskInstance: dag_with_postgres_operator_v02.insert_into_key_table manual__2025-01-08T02:56:58.038560+00:00 [queued]>
[2025-01-08T03:22:19.619+0000] {taskinstance.py:2866} INFO - Starting attempt 6 of 6
[2025-01-08T03:22:19.639+0000] {taskinstance.py:2889} INFO - Executing <Task(PostgresOperator): insert_into_key_table> on 2025-01-08 02:56:58.038560+00:00
[2025-01-08T03:22:19.650+0000] {logging_mixin.py:190} WARNING - /home/***/.local/lib/python3.12/site-packages/***/task/task_runner/standard_task_runner.py:70 DeprecationWarning: This process (pid=52983) is multi-threaded, use of fork() may lead to deadlocks in the child.
[2025-01-08T03:22:19.652+0000] {standard_task_runner.py:72} INFO - Started process 53028 to run task
[2025-01-08T03:22:19.651+0000] {standard_task_runner.py:104} INFO - Running: ['***', 'tasks', 'run', 'dag_with_postgres_operator_v02', 'insert_into_key_table', 'manual__2025-01-08T02:56:58.038560+00:00', '--job-id', '941', '--raw', '--subdir', 'DAGS_FOLDER/dag.py', '--cfg-path', '/tmp/tmpzcs0dcm7']
[2025-01-08T03:22:19.652+0000] {standard_task_runner.py:105} INFO - Job 941: Subtask insert_into_key_table
[2025-01-08T03:22:19.704+0000] {task_command.py:467} INFO - Running <TaskInstance: dag_with_postgres_operator_v02.insert_into_key_table manual__2025-01-08T02:56:58.038560+00:00 [running]> on host ec6dd3d48f26
[2025-01-08T03:22:19.792+0000] {taskinstance.py:3132} INFO - Exporting env vars: AIRFLOW_CTX_DAG_OWNER='coder2j' AIRFLOW_CTX_DAG_ID='dag_with_postgres_operator_v02' AIRFLOW_CTX_TASK_ID='insert_into_key_table' AIRFLOW_CTX_EXECUTION_DATE='2025-01-08T02:56:58.038560+00:00' AIRFLOW_CTX_TRY_NUMBER='6' AIRFLOW_CTX_DAG_RUN_ID='manual__2025-01-08T02:56:58.038560+00:00'
[2025-01-08T03:22:19.794+0000] {logging_mixin.py:190} INFO - Task instance is in running state
[2025-01-08T03:22:19.795+0000] {logging_mixin.py:190} INFO -  Previous state of the Task instance: queued
[2025-01-08T03:22:19.795+0000] {logging_mixin.py:190} INFO - Current task name:insert_into_key_table state:running start_date:2025-01-08 03:22:19.607261+00:00
[2025-01-08T03:22:19.796+0000] {logging_mixin.py:190} INFO - Dag name:dag_with_postgres_operator_v02 and current dag run status:running
[2025-01-08T03:22:19.796+0000] {taskinstance.py:731} INFO - ::endgroup::
[2025-01-08T03:22:19.797+0000] {sql.py:278} INFO - Executing: 
            INSERT INTO Keyy (CurrentPrice, DividendRate, BidAskSpread, FiftyTwoWeekHigh, FiftyTwoWeekLow, MarketCap, ROE, PegRatio, Company)
            VALUES
                
                (145.4, 5.42, 0.24, 183.41, 145.34, 199487340544, 0.48819, 1.7403, 'Pepsico'),
                (980.76, 20.4, 1.9500, 1082.45, 745.55, 151899144192, 0.1505, 1.7594, 'BlackRock');
        
[2025-01-08T03:22:19.806+0000] {base.py:84} INFO - Retrieving connection 'postgres_localhost'
[2025-01-08T03:22:19.814+0000] {base.py:84} INFO - Retrieving connection 'postgres_localhost'
[2025-01-08T03:22:19.818+0000] {sql.py:544} INFO - Running statement: 
            INSERT INTO Keyy (CurrentPrice, DividendRate, BidAskSpread, FiftyTwoWeekHigh, FiftyTwoWeekLow, MarketCap, ROE, PegRatio, Company)
            VALUES
                
                (145.4, 5.42, 0.24, 183.41, 145.34, 199487340544, 0.48819, 1.7403, 'Pepsico'),
                (980.76, 20.4, 1.9500, 1082.45, 745.55, 151899144192, 0.1505, 1.7594, 'BlackRock');
        , parameters: None
[2025-01-08T03:22:19.819+0000] {taskinstance.py:3311} ERROR - Task failed with exception
Traceback (most recent call last):
  File "/home/airflow/.local/lib/python3.12/site-packages/airflow/models/taskinstance.py", line 767, in _execute_task
    result = _execute_callable(context=context, **execute_callable_kwargs)
             ^^^^^^^^^^^^^^^^^^^^^^^^^^^^^^^^^^^^^^^^^^^^^^^^^^^^^^^^^^^^^
  File "/home/airflow/.local/lib/python3.12/site-packages/airflow/models/taskinstance.py", line 733, in _execute_callable
    return ExecutionCallableRunner(
           ^^^^^^^^^^^^^^^^^^^^^^^^
  File "/home/airflow/.local/lib/python3.12/site-packages/airflow/utils/operator_helpers.py", line 252, in run
    return self.func(*args, **kwargs)
           ^^^^^^^^^^^^^^^^^^^^^^^^^^
  File "/home/airflow/.local/lib/python3.12/site-packages/airflow/models/baseoperator.py", line 417, in wrapper
    return func(self, *args, **kwargs)
           ^^^^^^^^^^^^^^^^^^^^^^^^^^^
  File "/home/airflow/.local/lib/python3.12/site-packages/airflow/providers/common/sql/operators/sql.py", line 284, in execute
    output = hook.run(
             ^^^^^^^^^
  File "/home/airflow/.local/lib/python3.12/site-packages/airflow/providers/common/sql/hooks/sql.py", line 489, in run
    self._run_command(cur, sql_statement, parameters)
  File "/home/airflow/.local/lib/python3.12/site-packages/airflow/providers/common/sql/hooks/sql.py", line 549, in _run_command
    cur.execute(sql_statement)
psycopg2.errors.UniqueViolation: duplicate key value violates unique constraint "keyy_pkey"
DETAIL:  Key (currentprice)=(145.4) already exists.

[2025-01-08T03:22:19.828+0000] {logging_mixin.py:190} INFO - Task instance in failure state
[2025-01-08T03:22:19.829+0000] {logging_mixin.py:190} INFO - Task start:2025-01-08 03:22:19.607261+00:00 end:2025-01-08 03:22:19.828029+00:00 duration:0.220768
[2025-01-08T03:22:19.829+0000] {logging_mixin.py:190} INFO - Task:<Task(PostgresOperator): insert_into_key_table> dag:<DAG: dag_with_postgres_operator_v02> dagrun:<DagRun dag_with_postgres_operator_v02 @ 2025-01-08 02:56:58.038560+00:00: manual__2025-01-08T02:56:58.038560+00:00, state:running, queued_at: 2025-01-08 02:56:58.049599+00:00. externally triggered: True>
[2025-01-08T03:22:19.829+0000] {logging_mixin.py:190} INFO - Failure caused by duplicate key value violates unique constraint "keyy_pkey"
DETAIL:  Key (currentprice)=(145.4) already exists.
[2025-01-08T03:22:19.830+0000] {taskinstance.py:1225} INFO - Marking task as FAILED. dag_id=dag_with_postgres_operator_v02, task_id=insert_into_key_table, run_id=manual__2025-01-08T02:56:58.038560+00:00, execution_date=20250108T025658, start_date=20250108T032219, end_date=20250108T032219
[2025-01-08T03:22:19.841+0000] {taskinstance.py:340} INFO - ::group::Post task execution logs
[2025-01-08T03:22:19.842+0000] {standard_task_runner.py:124} ERROR - Failed to execute job 941 for task insert_into_key_table (duplicate key value violates unique constraint "keyy_pkey"
DETAIL:  Key (currentprice)=(145.4) already exists.
; 53028)
Traceback (most recent call last):
  File "/home/airflow/.local/lib/python3.12/site-packages/airflow/task/task_runner/standard_task_runner.py", line 117, in _start_by_fork
    ret = args.func(args, dag=self.dag)
          ^^^^^^^^^^^^^^^^^^^^^^^^^^^^^
  File "/home/airflow/.local/lib/python3.12/site-packages/airflow/cli/cli_config.py", line 49, in command
    return func(*args, **kwargs)
           ^^^^^^^^^^^^^^^^^^^^^
  File "/home/airflow/.local/lib/python3.12/site-packages/airflow/utils/cli.py", line 116, in wrapper
    return f(*args, **kwargs)
           ^^^^^^^^^^^^^^^^^^
  File "/home/airflow/.local/lib/python3.12/site-packages/airflow/cli/commands/task_command.py", line 483, in task_run
    task_return_code = _run_task_by_selected_method(args, _dag, ti)
                       ^^^^^^^^^^^^^^^^^^^^^^^^^^^^^^^^^^^^^^^^^^^^
  File "/home/airflow/.local/lib/python3.12/site-packages/airflow/cli/commands/task_command.py", line 256, in _run_task_by_selected_method
    return _run_raw_task(args, ti)
           ^^^^^^^^^^^^^^^^^^^^^^^
  File "/home/airflow/.local/lib/python3.12/site-packages/airflow/cli/commands/task_command.py", line 341, in _run_raw_task
    return ti._run_raw_task(
           ^^^^^^^^^^^^^^^^^
  File "/home/airflow/.local/lib/python3.12/site-packages/airflow/utils/session.py", line 97, in wrapper
    return func(*args, session=session, **kwargs)
           ^^^^^^^^^^^^^^^^^^^^^^^^^^^^^^^^^^^^^^
  File "/home/airflow/.local/lib/python3.12/site-packages/airflow/models/taskinstance.py", line 3005, in _run_raw_task
    return _run_raw_task(
           ^^^^^^^^^^^^^^
  File "/home/airflow/.local/lib/python3.12/site-packages/airflow/models/taskinstance.py", line 273, in _run_raw_task
    TaskInstance._execute_task_with_callbacks(
  File "/home/airflow/.local/lib/python3.12/site-packages/airflow/models/taskinstance.py", line 3159, in _execute_task_with_callbacks
    result = self._execute_task(context, task_orig)
             ^^^^^^^^^^^^^^^^^^^^^^^^^^^^^^^^^^^^^^
  File "/home/airflow/.local/lib/python3.12/site-packages/airflow/models/taskinstance.py", line 3183, in _execute_task
    return _execute_task(self, context, task_orig)
           ^^^^^^^^^^^^^^^^^^^^^^^^^^^^^^^^^^^^^^^
  File "/home/airflow/.local/lib/python3.12/site-packages/airflow/models/taskinstance.py", line 767, in _execute_task
    result = _execute_callable(context=context, **execute_callable_kwargs)
             ^^^^^^^^^^^^^^^^^^^^^^^^^^^^^^^^^^^^^^^^^^^^^^^^^^^^^^^^^^^^^
  File "/home/airflow/.local/lib/python3.12/site-packages/airflow/models/taskinstance.py", line 733, in _execute_callable
    return ExecutionCallableRunner(
           ^^^^^^^^^^^^^^^^^^^^^^^^
  File "/home/airflow/.local/lib/python3.12/site-packages/airflow/utils/operator_helpers.py", line 252, in run
    return self.func(*args, **kwargs)
           ^^^^^^^^^^^^^^^^^^^^^^^^^^
  File "/home/airflow/.local/lib/python3.12/site-packages/airflow/models/baseoperator.py", line 417, in wrapper
    return func(self, *args, **kwargs)
           ^^^^^^^^^^^^^^^^^^^^^^^^^^^
  File "/home/airflow/.local/lib/python3.12/site-packages/airflow/providers/common/sql/operators/sql.py", line 284, in execute
    output = hook.run(
             ^^^^^^^^^
  File "/home/airflow/.local/lib/python3.12/site-packages/airflow/providers/common/sql/hooks/sql.py", line 489, in run
    self._run_command(cur, sql_statement, parameters)
  File "/home/airflow/.local/lib/python3.12/site-packages/airflow/providers/common/sql/hooks/sql.py", line 549, in _run_command
    cur.execute(sql_statement)
psycopg2.errors.UniqueViolation: duplicate key value violates unique constraint "keyy_pkey"
DETAIL:  Key (currentprice)=(145.4) already exists.

[2025-01-08T03:22:19.869+0000] {local_task_job_runner.py:266} INFO - Task exited with return code 1
[2025-01-08T03:22:19.877+0000] {local_task_job_runner.py:245} INFO - ::endgroup::
