[2024-12-06T04:57:24.709+0000] {local_task_job_runner.py:123} INFO - ::group::Pre task execution logs
[2024-12-06T04:57:24.927+0000] {taskinstance.py:2613} INFO - Dependencies all met for dep_context=non-requeueable deps ti=<TaskInstance: dag_with_postgres_operator_v02.insert_into_flow_table manual__2024-12-06T04:56:43.927065+00:00 [queued]>
[2024-12-06T04:57:24.993+0000] {taskinstance.py:2613} INFO - Dependencies all met for dep_context=requeueable deps ti=<TaskInstance: dag_with_postgres_operator_v02.insert_into_flow_table manual__2024-12-06T04:56:43.927065+00:00 [queued]>
[2024-12-06T04:57:25.032+0000] {taskinstance.py:2866} INFO - Starting attempt 1 of 6
[2024-12-06T04:57:25.113+0000] {taskinstance.py:2889} INFO - Executing <Task(PostgresOperator): insert_into_flow_table> on 2024-12-06 04:56:43.927065+00:00
[2024-12-06T04:57:25.235+0000] {warnings.py:112} WARNING - /home/***/.local/lib/python3.12/site-packages/***/task/task_runner/standard_task_runner.py:70: DeprecationWarning: This process (pid=2454) is multi-threaded, use of fork() may lead to deadlocks in the child.
  pid = os.fork()

[2024-12-06T04:57:25.235+0000] {standard_task_runner.py:104} INFO - Running: ['***', 'tasks', 'run', 'dag_with_postgres_operator_v02', 'insert_into_flow_table', 'manual__2024-12-06T04:56:43.927065+00:00', '--job-id', '577', '--raw', '--subdir', 'DAGS_FOLDER/dag.py', '--cfg-path', '/tmp/tmpxjtre2xe']
[2024-12-06T04:57:25.238+0000] {standard_task_runner.py:72} INFO - Started process 2475 to run task
[2024-12-06T04:57:25.239+0000] {standard_task_runner.py:105} INFO - Job 577: Subtask insert_into_flow_table
[2024-12-06T04:57:37.429+0000] {task_command.py:467} INFO - Running <TaskInstance: dag_with_postgres_operator_v02.insert_into_flow_table manual__2024-12-06T04:56:43.927065+00:00 [running]> on host 9ed27289a118
[2024-12-06T04:57:38.574+0000] {taskinstance.py:3132} INFO - Exporting env vars: AIRFLOW_CTX_DAG_OWNER='coder2j' AIRFLOW_CTX_DAG_ID='dag_with_postgres_operator_v02' AIRFLOW_CTX_TASK_ID='insert_into_flow_table' AIRFLOW_CTX_EXECUTION_DATE='2024-12-06T04:56:43.927065+00:00' AIRFLOW_CTX_TRY_NUMBER='1' AIRFLOW_CTX_DAG_RUN_ID='manual__2024-12-06T04:56:43.927065+00:00'
[2024-12-06T04:57:38.582+0000] {logging_mixin.py:190} INFO - Task instance is in running state
[2024-12-06T04:57:38.601+0000] {logging_mixin.py:190} INFO -  Previous state of the Task instance: queued
[2024-12-06T04:57:38.618+0000] {logging_mixin.py:190} INFO - Current task name:insert_into_flow_table state:running start_date:2024-12-06 04:57:24.932229+00:00
[2024-12-06T04:57:38.630+0000] {logging_mixin.py:190} INFO - Dag name:dag_with_postgres_operator_v02 and current dag run status:running
[2024-12-06T04:57:38.656+0000] {taskinstance.py:731} INFO - ::endgroup::
[2024-12-06T04:57:38.662+0000] {sql.py:278} INFO - Executing: 
            INSERT INTO Flow (FreeCashFlow,CapitalExpenditure,Year,Company)
            VALUES
                (74071000000.0,-44477000000.0,2021,'Microsoft'),
                (59475000000.0,-28107000000.0,2022,'Microsoft'),
                (65149000000.0,-23886000000.0,2023,'Microsoft'),
                (56118000000.0,-20622000000.0,2024,'Microsoft');
        
[2024-12-06T04:57:38.765+0000] {base.py:84} INFO - Retrieving connection 'postgres_localhost'
[2024-12-06T04:57:38.831+0000] {base.py:84} INFO - Retrieving connection 'postgres_localhost'
[2024-12-06T04:57:39.088+0000] {taskinstance.py:3311} ERROR - Task failed with exception
Traceback (most recent call last):
  File "/home/airflow/.local/lib/python3.12/site-packages/airflow/models/taskinstance.py", line 767, in _execute_task
    result = _execute_callable(context=context, **execute_callable_kwargs)
             ^^^^^^^^^^^^^^^^^^^^^^^^^^^^^^^^^^^^^^^^^^^^^^^^^^^^^^^^^^^^^
  File "/home/airflow/.local/lib/python3.12/site-packages/airflow/models/taskinstance.py", line 733, in _execute_callable
    return ExecutionCallableRunner(
           ^^^^^^^^^^^^^^^^^^^^^^^^
  File "/home/airflow/.local/lib/python3.12/site-packages/airflow/utils/operator_helpers.py", line 252, in run
    return self.func(*args, **kwargs)
           ^^^^^^^^^^^^^^^^^^^^^^^^^^
  File "/home/airflow/.local/lib/python3.12/site-packages/airflow/models/baseoperator.py", line 417, in wrapper
    return func(self, *args, **kwargs)
           ^^^^^^^^^^^^^^^^^^^^^^^^^^^
  File "/home/airflow/.local/lib/python3.12/site-packages/airflow/providers/common/sql/operators/sql.py", line 284, in execute
    output = hook.run(
             ^^^^^^^^^
  File "/home/airflow/.local/lib/python3.12/site-packages/airflow/providers/common/sql/hooks/sql.py", line 485, in run
    with self._create_autocommit_connection(autocommit) as conn:
         ^^^^^^^^^^^^^^^^^^^^^^^^^^^^^^^^^^^^^^^^^^^^^^
  File "/usr/local/lib/python3.12/contextlib.py", line 137, in __enter__
    return next(self.gen)
           ^^^^^^^^^^^^^^
  File "/home/airflow/.local/lib/python3.12/site-packages/airflow/providers/common/sql/hooks/sql.py", line 609, in _create_autocommit_connection
    with closing(self.get_conn()) as conn:
                 ^^^^^^^^^^^^^^^
  File "/home/airflow/.local/lib/python3.12/site-packages/airflow/providers/postgres/hooks/postgres.py", line 181, in get_conn
    self.conn = psycopg2.connect(**conn_args)
                ^^^^^^^^^^^^^^^^^^^^^^^^^^^^^
  File "/home/airflow/.local/lib/python3.12/site-packages/psycopg2/__init__.py", line 122, in connect
    conn = _connect(dsn, connection_factory=connection_factory, **kwasync)
           ^^^^^^^^^^^^^^^^^^^^^^^^^^^^^^^^^^^^^^^^^^^^^^^^^^^^^^^^^^^^^^^
psycopg2.OperationalError: connection to server at "host.docker.internal" (192.168.65.254), port 5432 failed: FATAL:  password authentication failed for user "***"

[2024-12-06T04:57:39.215+0000] {logging_mixin.py:190} INFO - Task instance in failure state
[2024-12-06T04:57:39.223+0000] {logging_mixin.py:190} INFO - Task start:2024-12-06 04:57:24.932229+00:00 end:2024-12-06 04:57:39.205159+00:00 duration:14.27293
[2024-12-06T04:57:39.229+0000] {logging_mixin.py:190} INFO - Task:<Task(PostgresOperator): insert_into_flow_table> dag:<DAG: dag_with_postgres_operator_v02> dagrun:<DagRun dag_with_postgres_operator_v02 @ 2024-12-06 04:56:43.927065+00:00: manual__2024-12-06T04:56:43.927065+00:00, state:running, queued_at: 2024-12-06 04:56:44.175593+00:00. externally triggered: True>
[2024-12-06T04:57:39.235+0000] {logging_mixin.py:190} INFO - Failure caused by connection to server at "host.docker.internal" (192.168.65.254), port 5432 failed: FATAL:  password authentication failed for user "***"
[2024-12-06T04:57:39.248+0000] {taskinstance.py:1225} INFO - Marking task as UP_FOR_RETRY. dag_id=dag_with_postgres_operator_v02, task_id=insert_into_flow_table, run_id=manual__2024-12-06T04:56:43.927065+00:00, execution_date=20241206T045643, start_date=20241206T045724, end_date=20241206T045739
[2024-12-06T04:57:39.597+0000] {taskinstance.py:340} INFO - ::group::Post task execution logs
[2024-12-06T04:57:39.613+0000] {standard_task_runner.py:124} ERROR - Failed to execute job 577 for task insert_into_flow_table (connection to server at "host.docker.internal" (192.168.65.254), port 5432 failed: FATAL:  password authentication failed for user "***"
; 2475)
Traceback (most recent call last):
  File "/home/airflow/.local/lib/python3.12/site-packages/airflow/task/task_runner/standard_task_runner.py", line 117, in _start_by_fork
    ret = args.func(args, dag=self.dag)
          ^^^^^^^^^^^^^^^^^^^^^^^^^^^^^
  File "/home/airflow/.local/lib/python3.12/site-packages/airflow/cli/cli_config.py", line 49, in command
    return func(*args, **kwargs)
           ^^^^^^^^^^^^^^^^^^^^^
  File "/home/airflow/.local/lib/python3.12/site-packages/airflow/utils/cli.py", line 116, in wrapper
    return f(*args, **kwargs)
           ^^^^^^^^^^^^^^^^^^
  File "/home/airflow/.local/lib/python3.12/site-packages/airflow/cli/commands/task_command.py", line 483, in task_run
    task_return_code = _run_task_by_selected_method(args, _dag, ti)
                       ^^^^^^^^^^^^^^^^^^^^^^^^^^^^^^^^^^^^^^^^^^^^
  File "/home/airflow/.local/lib/python3.12/site-packages/airflow/cli/commands/task_command.py", line 256, in _run_task_by_selected_method
    return _run_raw_task(args, ti)
           ^^^^^^^^^^^^^^^^^^^^^^^
  File "/home/airflow/.local/lib/python3.12/site-packages/airflow/cli/commands/task_command.py", line 341, in _run_raw_task
    return ti._run_raw_task(
           ^^^^^^^^^^^^^^^^^
  File "/home/airflow/.local/lib/python3.12/site-packages/airflow/utils/session.py", line 97, in wrapper
    return func(*args, session=session, **kwargs)
           ^^^^^^^^^^^^^^^^^^^^^^^^^^^^^^^^^^^^^^
  File "/home/airflow/.local/lib/python3.12/site-packages/airflow/models/taskinstance.py", line 3005, in _run_raw_task
    return _run_raw_task(
           ^^^^^^^^^^^^^^
  File "/home/airflow/.local/lib/python3.12/site-packages/airflow/models/taskinstance.py", line 273, in _run_raw_task
    TaskInstance._execute_task_with_callbacks(
  File "/home/airflow/.local/lib/python3.12/site-packages/airflow/models/taskinstance.py", line 3159, in _execute_task_with_callbacks
    result = self._execute_task(context, task_orig)
             ^^^^^^^^^^^^^^^^^^^^^^^^^^^^^^^^^^^^^^
  File "/home/airflow/.local/lib/python3.12/site-packages/airflow/models/taskinstance.py", line 3183, in _execute_task
    return _execute_task(self, context, task_orig)
           ^^^^^^^^^^^^^^^^^^^^^^^^^^^^^^^^^^^^^^^
  File "/home/airflow/.local/lib/python3.12/site-packages/airflow/models/taskinstance.py", line 767, in _execute_task
    result = _execute_callable(context=context, **execute_callable_kwargs)
             ^^^^^^^^^^^^^^^^^^^^^^^^^^^^^^^^^^^^^^^^^^^^^^^^^^^^^^^^^^^^^
  File "/home/airflow/.local/lib/python3.12/site-packages/airflow/models/taskinstance.py", line 733, in _execute_callable
    return ExecutionCallableRunner(
           ^^^^^^^^^^^^^^^^^^^^^^^^
  File "/home/airflow/.local/lib/python3.12/site-packages/airflow/utils/operator_helpers.py", line 252, in run
    return self.func(*args, **kwargs)
           ^^^^^^^^^^^^^^^^^^^^^^^^^^
  File "/home/airflow/.local/lib/python3.12/site-packages/airflow/models/baseoperator.py", line 417, in wrapper
    return func(self, *args, **kwargs)
           ^^^^^^^^^^^^^^^^^^^^^^^^^^^
  File "/home/airflow/.local/lib/python3.12/site-packages/airflow/providers/common/sql/operators/sql.py", line 284, in execute
    output = hook.run(
             ^^^^^^^^^
  File "/home/airflow/.local/lib/python3.12/site-packages/airflow/providers/common/sql/hooks/sql.py", line 485, in run
    with self._create_autocommit_connection(autocommit) as conn:
         ^^^^^^^^^^^^^^^^^^^^^^^^^^^^^^^^^^^^^^^^^^^^^^
  File "/usr/local/lib/python3.12/contextlib.py", line 137, in __enter__
    return next(self.gen)
           ^^^^^^^^^^^^^^
  File "/home/airflow/.local/lib/python3.12/site-packages/airflow/providers/common/sql/hooks/sql.py", line 609, in _create_autocommit_connection
    with closing(self.get_conn()) as conn:
                 ^^^^^^^^^^^^^^^
  File "/home/airflow/.local/lib/python3.12/site-packages/airflow/providers/postgres/hooks/postgres.py", line 181, in get_conn
    self.conn = psycopg2.connect(**conn_args)
                ^^^^^^^^^^^^^^^^^^^^^^^^^^^^^
  File "/home/airflow/.local/lib/python3.12/site-packages/psycopg2/__init__.py", line 122, in connect
    conn = _connect(dsn, connection_factory=connection_factory, **kwasync)
           ^^^^^^^^^^^^^^^^^^^^^^^^^^^^^^^^^^^^^^^^^^^^^^^^^^^^^^^^^^^^^^^
psycopg2.OperationalError: connection to server at "host.docker.internal" (192.168.65.254), port 5432 failed: FATAL:  password authentication failed for user "***"

[2024-12-06T04:57:39.777+0000] {local_task_job_runner.py:266} INFO - Task exited with return code 1
[2024-12-06T04:57:39.944+0000] {taskinstance.py:3895} INFO - 0 downstream tasks scheduled from follow-on schedule check
[2024-12-06T04:57:39.966+0000] {local_task_job_runner.py:245} INFO - ::endgroup::
