[2025-01-08T03:01:51.301+0000] {local_task_job_runner.py:123} INFO - ::group::Pre task execution logs
[2025-01-08T03:01:51.376+0000] {taskinstance.py:2613} INFO - Dependencies all met for dep_context=non-requeueable deps ti=<TaskInstance: dag_with_postgres_operator_v02.insert_into_curr_table manual__2025-01-08T02:46:37.243913+00:00 [queued]>
[2025-01-08T03:01:51.411+0000] {taskinstance.py:2613} INFO - Dependencies all met for dep_context=requeueable deps ti=<TaskInstance: dag_with_postgres_operator_v02.insert_into_curr_table manual__2025-01-08T02:46:37.243913+00:00 [queued]>
[2025-01-08T03:01:51.414+0000] {taskinstance.py:2866} INFO - Starting attempt 4 of 6
[2025-01-08T03:01:51.466+0000] {taskinstance.py:2889} INFO - Executing <Task(PostgresOperator): insert_into_curr_table> on 2025-01-08 02:46:37.243913+00:00
[2025-01-08T03:01:51.501+0000] {standard_task_runner.py:104} INFO - Running: ['***', 'tasks', 'run', 'dag_with_postgres_operator_v02', 'insert_into_curr_table', 'manual__2025-01-08T02:46:37.243913+00:00', '--job-id', '878', '--raw', '--subdir', 'DAGS_FOLDER/dag.py', '--cfg-path', '/tmp/tmp_7ocbq00']
[2025-01-08T03:01:51.504+0000] {standard_task_runner.py:105} INFO - Job 878: Subtask insert_into_curr_table
[2025-01-08T03:01:51.509+0000] {logging_mixin.py:190} WARNING - /home/***/.local/lib/python3.12/site-packages/***/task/task_runner/standard_task_runner.py:70 DeprecationWarning: This process (pid=41050) is multi-threaded, use of fork() may lead to deadlocks in the child.
[2025-01-08T03:01:51.511+0000] {standard_task_runner.py:72} INFO - Started process 41080 to run task
[2025-01-08T03:01:51.682+0000] {task_command.py:467} INFO - Running <TaskInstance: dag_with_postgres_operator_v02.insert_into_curr_table manual__2025-01-08T02:46:37.243913+00:00 [running]> on host ec6dd3d48f26
[2025-01-08T03:01:51.880+0000] {taskinstance.py:3132} INFO - Exporting env vars: AIRFLOW_CTX_DAG_OWNER='coder2j' AIRFLOW_CTX_DAG_ID='dag_with_postgres_operator_v02' AIRFLOW_CTX_TASK_ID='insert_into_curr_table' AIRFLOW_CTX_EXECUTION_DATE='2025-01-08T02:46:37.243913+00:00' AIRFLOW_CTX_TRY_NUMBER='4' AIRFLOW_CTX_DAG_RUN_ID='manual__2025-01-08T02:46:37.243913+00:00'
[2025-01-08T03:01:51.887+0000] {logging_mixin.py:190} INFO - Task instance is in running state
[2025-01-08T03:01:51.890+0000] {logging_mixin.py:190} INFO -  Previous state of the Task instance: queued
[2025-01-08T03:01:51.892+0000] {logging_mixin.py:190} INFO - Current task name:insert_into_curr_table state:running start_date:2025-01-08 03:01:51.384352+00:00
[2025-01-08T03:01:51.893+0000] {logging_mixin.py:190} INFO - Dag name:dag_with_postgres_operator_v02 and current dag run status:running
[2025-01-08T03:01:51.894+0000] {taskinstance.py:731} INFO - ::endgroup::
[2025-01-08T03:01:51.895+0000] {sql.py:278} INFO - Executing: 
            INSERT INTO Curr (ShortTerm, Receivables, Inventory, HedgingAssetsCurrently, OtherCurrentAssets, Company)
            VALUES
                
                (37.1, 40.1, 0.8, 19.8, 3.0, 'Pepsico'),
                (35.6, 42.3, 0.9, 18.5, 3.5, 'BlackRock');
        
[2025-01-08T03:01:51.914+0000] {base.py:84} INFO - Retrieving connection 'postgres_localhost'
[2025-01-08T03:01:51.928+0000] {base.py:84} INFO - Retrieving connection 'postgres_localhost'
[2025-01-08T03:01:51.934+0000] {sql.py:544} INFO - Running statement: 
            INSERT INTO Curr (ShortTerm, Receivables, Inventory, HedgingAssetsCurrently, OtherCurrentAssets, Company)
            VALUES
                
                (37.1, 40.1, 0.8, 19.8, 3.0, 'Pepsico'),
                (35.6, 42.3, 0.9, 18.5, 3.5, 'BlackRock');
        , parameters: None
[2025-01-08T03:01:51.938+0000] {taskinstance.py:3311} ERROR - Task failed with exception
Traceback (most recent call last):
  File "/home/airflow/.local/lib/python3.12/site-packages/airflow/models/taskinstance.py", line 767, in _execute_task
    result = _execute_callable(context=context, **execute_callable_kwargs)
             ^^^^^^^^^^^^^^^^^^^^^^^^^^^^^^^^^^^^^^^^^^^^^^^^^^^^^^^^^^^^^
  File "/home/airflow/.local/lib/python3.12/site-packages/airflow/models/taskinstance.py", line 733, in _execute_callable
    return ExecutionCallableRunner(
           ^^^^^^^^^^^^^^^^^^^^^^^^
  File "/home/airflow/.local/lib/python3.12/site-packages/airflow/utils/operator_helpers.py", line 252, in run
    return self.func(*args, **kwargs)
           ^^^^^^^^^^^^^^^^^^^^^^^^^^
  File "/home/airflow/.local/lib/python3.12/site-packages/airflow/models/baseoperator.py", line 417, in wrapper
    return func(self, *args, **kwargs)
           ^^^^^^^^^^^^^^^^^^^^^^^^^^^
  File "/home/airflow/.local/lib/python3.12/site-packages/airflow/providers/common/sql/operators/sql.py", line 284, in execute
    output = hook.run(
             ^^^^^^^^^
  File "/home/airflow/.local/lib/python3.12/site-packages/airflow/providers/common/sql/hooks/sql.py", line 489, in run
    self._run_command(cur, sql_statement, parameters)
  File "/home/airflow/.local/lib/python3.12/site-packages/airflow/providers/common/sql/hooks/sql.py", line 549, in _run_command
    cur.execute(sql_statement)
psycopg2.errors.UniqueViolation: duplicate key value violates unique constraint "curr_pkey"
DETAIL:  Key (shortterm)=(37.1) already exists.

[2025-01-08T03:01:51.965+0000] {logging_mixin.py:190} INFO - Task instance in failure state
[2025-01-08T03:01:51.966+0000] {logging_mixin.py:190} INFO - Task start:2025-01-08 03:01:51.384352+00:00 end:2025-01-08 03:01:51.964045+00:00 duration:0.579693
[2025-01-08T03:01:51.966+0000] {logging_mixin.py:190} INFO - Task:<Task(PostgresOperator): insert_into_curr_table> dag:<DAG: dag_with_postgres_operator_v02> dagrun:<DagRun dag_with_postgres_operator_v02 @ 2025-01-08 02:46:37.243913+00:00: manual__2025-01-08T02:46:37.243913+00:00, state:running, queued_at: 2025-01-08 02:46:37.254149+00:00. externally triggered: True>
[2025-01-08T03:01:51.969+0000] {logging_mixin.py:190} INFO - Failure caused by duplicate key value violates unique constraint "curr_pkey"
DETAIL:  Key (shortterm)=(37.1) already exists.
[2025-01-08T03:01:51.970+0000] {taskinstance.py:1225} INFO - Marking task as UP_FOR_RETRY. dag_id=dag_with_postgres_operator_v02, task_id=insert_into_curr_table, run_id=manual__2025-01-08T02:46:37.243913+00:00, execution_date=20250108T024637, start_date=20250108T030151, end_date=20250108T030151
[2025-01-08T03:01:52.004+0000] {taskinstance.py:340} INFO - ::group::Post task execution logs
[2025-01-08T03:01:52.005+0000] {standard_task_runner.py:124} ERROR - Failed to execute job 878 for task insert_into_curr_table (duplicate key value violates unique constraint "curr_pkey"
DETAIL:  Key (shortterm)=(37.1) already exists.
; 41080)
Traceback (most recent call last):
  File "/home/airflow/.local/lib/python3.12/site-packages/airflow/task/task_runner/standard_task_runner.py", line 117, in _start_by_fork
    ret = args.func(args, dag=self.dag)
          ^^^^^^^^^^^^^^^^^^^^^^^^^^^^^
  File "/home/airflow/.local/lib/python3.12/site-packages/airflow/cli/cli_config.py", line 49, in command
    return func(*args, **kwargs)
           ^^^^^^^^^^^^^^^^^^^^^
  File "/home/airflow/.local/lib/python3.12/site-packages/airflow/utils/cli.py", line 116, in wrapper
    return f(*args, **kwargs)
           ^^^^^^^^^^^^^^^^^^
  File "/home/airflow/.local/lib/python3.12/site-packages/airflow/cli/commands/task_command.py", line 483, in task_run
    task_return_code = _run_task_by_selected_method(args, _dag, ti)
                       ^^^^^^^^^^^^^^^^^^^^^^^^^^^^^^^^^^^^^^^^^^^^
  File "/home/airflow/.local/lib/python3.12/site-packages/airflow/cli/commands/task_command.py", line 256, in _run_task_by_selected_method
    return _run_raw_task(args, ti)
           ^^^^^^^^^^^^^^^^^^^^^^^
  File "/home/airflow/.local/lib/python3.12/site-packages/airflow/cli/commands/task_command.py", line 341, in _run_raw_task
    return ti._run_raw_task(
           ^^^^^^^^^^^^^^^^^
  File "/home/airflow/.local/lib/python3.12/site-packages/airflow/utils/session.py", line 97, in wrapper
    return func(*args, session=session, **kwargs)
           ^^^^^^^^^^^^^^^^^^^^^^^^^^^^^^^^^^^^^^
  File "/home/airflow/.local/lib/python3.12/site-packages/airflow/models/taskinstance.py", line 3005, in _run_raw_task
    return _run_raw_task(
           ^^^^^^^^^^^^^^
  File "/home/airflow/.local/lib/python3.12/site-packages/airflow/models/taskinstance.py", line 273, in _run_raw_task
    TaskInstance._execute_task_with_callbacks(
  File "/home/airflow/.local/lib/python3.12/site-packages/airflow/models/taskinstance.py", line 3159, in _execute_task_with_callbacks
    result = self._execute_task(context, task_orig)
             ^^^^^^^^^^^^^^^^^^^^^^^^^^^^^^^^^^^^^^
  File "/home/airflow/.local/lib/python3.12/site-packages/airflow/models/taskinstance.py", line 3183, in _execute_task
    return _execute_task(self, context, task_orig)
           ^^^^^^^^^^^^^^^^^^^^^^^^^^^^^^^^^^^^^^^
  File "/home/airflow/.local/lib/python3.12/site-packages/airflow/models/taskinstance.py", line 767, in _execute_task
    result = _execute_callable(context=context, **execute_callable_kwargs)
             ^^^^^^^^^^^^^^^^^^^^^^^^^^^^^^^^^^^^^^^^^^^^^^^^^^^^^^^^^^^^^
  File "/home/airflow/.local/lib/python3.12/site-packages/airflow/models/taskinstance.py", line 733, in _execute_callable
    return ExecutionCallableRunner(
           ^^^^^^^^^^^^^^^^^^^^^^^^
  File "/home/airflow/.local/lib/python3.12/site-packages/airflow/utils/operator_helpers.py", line 252, in run
    return self.func(*args, **kwargs)
           ^^^^^^^^^^^^^^^^^^^^^^^^^^
  File "/home/airflow/.local/lib/python3.12/site-packages/airflow/models/baseoperator.py", line 417, in wrapper
    return func(self, *args, **kwargs)
           ^^^^^^^^^^^^^^^^^^^^^^^^^^^
  File "/home/airflow/.local/lib/python3.12/site-packages/airflow/providers/common/sql/operators/sql.py", line 284, in execute
    output = hook.run(
             ^^^^^^^^^
  File "/home/airflow/.local/lib/python3.12/site-packages/airflow/providers/common/sql/hooks/sql.py", line 489, in run
    self._run_command(cur, sql_statement, parameters)
  File "/home/airflow/.local/lib/python3.12/site-packages/airflow/providers/common/sql/hooks/sql.py", line 549, in _run_command
    cur.execute(sql_statement)
psycopg2.errors.UniqueViolation: duplicate key value violates unique constraint "curr_pkey"
DETAIL:  Key (shortterm)=(37.1) already exists.

[2025-01-08T03:01:52.050+0000] {local_task_job_runner.py:266} INFO - Task exited with return code 1
[2025-01-08T03:01:52.089+0000] {taskinstance.py:3895} INFO - 0 downstream tasks scheduled from follow-on schedule check
[2025-01-08T03:01:52.092+0000] {local_task_job_runner.py:245} INFO - ::endgroup::
